Workbook

Sheet 2016 (rev3)
B3: PRODUCCIÓN MENSUAL DE ENERGÍA ELÉCTRICA EN EGASA
B4: AÑO 2016 (MWh)
B6: CENTRALES | C6: Enero | D6: Febrero | E6: Marzo | F6: Abril | G6: Mayo | H6: Junio | I6: Julio | J6: Agosto | K6: Septiembre | L6: Octubre | M6: Noviembre | N6: Diciembre | O6: Acumulado
B7: Hidráulica
B8: Charcani I | C8: 1200.3127 | D8: 595.62766 | E8: 1109.2468 | F8: 1127.1816 | G8: 1133.3096 | H8: 1135.6821 | I8: 1181.7817 | J8: 1185.2003 | K8: 1181.474 | L8: 1245.8838 | M8: 1178.9328 | N8: 1245.6465 | O8: =+SUM(C8:N8) -> 13520.279
B9: Charcani II | C9: 417.6062 | D9: 355.83638 | E9: 413.04622 | F9: 403.44701 | G9: 410.37315 | H9: 394.81751 | I9: 287.22853 | J9: 401.31071 | K9: 411.91617 | L9: 423.46907 | M9: 403.90083 | N9: 420.58886 | O9: =+SUM(C9:N9) -> 4743.5406
B10: Charcani III | C10: 3348.0482 | D10: 2962.1098 | E10: 3255.6861 | F10: 3265.2526 | G10: 3232.8522 | H10: 3255.7149 | I10: 3359.2217 | J10: 3320.3623 | K10: 3241.1074 | L10: 3349.2048 | M10: 3199.8066 | N10: 3378.4625 | O10: =+SUM(C10:N10) -> 39167.829
B11: Charcani IV | C11: 7625.7598 | D11: 7253.5199 | E11: 7647.2709 | F11: 7324.9903 | G11: 7284.2654 | H11: 7247.1245 | I11: 7492.9544 | J11: 7411.6765 | K11: 7936.2177 | L11: 8130.645 | M11: 7772.5023 | N11: 7774.0505 | O11: =+SUM(C11:N11) -> 90900.977
B12: Charcani V | C12: 44560.97 | D12: 51114.303 | E12: 45291.949 | F12: 43101.63 | G12: 44554.95 | H12: 43092.401 | I12: 44548.85 | J12: 44536.922 | K12: 47393.736 | L12: 48996.122 | M12: 47409.62 | N12: 46748.368 | O12: =+SUM(C12:N12) -> 551349.82
B13: Charcani VI | C13: 4414.3695 | D13: 4126.7638 | E13: 4482.7831 | F13: 4195.4087 | G13: 4473.8741 | H13: 4304.7715 | I13: 4513.0974 | J13: 4425.3353 | K13: 4583.0286 | L13: 4722.4734 | M13: 4106.3715 | N13: 4463.2136 | O13: =+SUM(C13:N13) -> 52811.49
B14: Total Hidraúlica | C14: =SUM(C8:C13) -> 61567.067 | D14: =SUM(D8:D13) -> 66408.16 | E14: =SUM(E8:E13) -> 62199.982 | F14: =SUM(F8:F13) -> 59417.911 | G14: =SUM(G8:G13) -> 61089.624 | H14: =SUM(H8:H13) -> 59430.512 | I14: =SUM(I8:I13) -> 61383.133 | J14: =SUM(J8:J13) -> 61280.807 | ... N14: =SUM(N8:N13) -> 64030.33 | O14: =+SUM(C14:N14) -> 752493.94
B15: Térmica
B16: T.Vapor | C16: 0 | D16: 0 | E16: 0 | F16: 0 | G16: 0 | H16: 0 | I16: 0 | J16: 0 | K16: 0 | L16: 0 | M16: 0 | N16: 0 | O16: =+SUM(C16:N16) -> 0
B17: T.G.-Ciclo Combinado | C17: 134.52245 | D17: 54.015014 | E17: 72.848699 | F17: 48.837975 | G17: 52.559226 | H17: 0 | I17: 54.399136 | J17: 0 | K17: 0 | L17: 57.050833 | M17: 28.55654 | N17: 0 | O17: =+SUM(C17:N17) -> 502.78987
B18: Sulzers | C18: 2898.6855 | D18: 2115.9897 | E18: 339.40915 | F18: 240.20707 | G18: 1612.7645 | H18: 2753.1754 | I18: 3111.3778 | J18: 4587.8711 | K18: 4150.3115 | L18: 1122.1332 | M18: 3499.8228 | N18: 1063.9934 | O18: =+SUM(C18:N18) -> 27495.741
B19: C.T. Mollendo | C19: 4696.5428 | D19: 2367.8451 | E19: 341.36491 | F19: 353.19135 | G19: 2436.2082 | H19: 2605.0519 | I19: 1853.8934 | J19: 2984.2871 | K19: 1357.986 | L19: 391.94482 | M19: 4093.6307 | N19: 1769.7624 | O19: =+SUM(C19:N19) -> 25251.709
B20: C.T. Pisco | C20: 30896.331 | D20: 40302.368 | E20: 37376.767 | F20: 44975.479 | G20: 49165.363 | H20: 46126.459 | I20: 48407.289 | J20: 50743.657 | K20: 45292.577 | L20: 52765.779 | M20: 49098.928 | N20: 44732.824 | O20: =+SUM(C20:N20) -> 539883.82
B21: Total Térmica | C21: =SUM(C16:C20) -> 38626.082 | D21: =SUM(D16:D20) -> 44840.218 | E21: =SUM(E16:E20) -> 38130.39 | F21: =SUM(F16:F20) -> 45617.716 | G21: =SUM(G16:G20) -> 53266.895 | H21: =SUM(H16:H20) -> 51484.687 | I21: =SUM(I16:I20) -> 53426.96 | J21: =SUM(J16:J20) -> 58315.816 | ... N21: =SUM(N16:N20) -> 47566.58 | O21: =+SUM(C21:N21) -> 593134.06
B22: TOTAL EGASA | C22: =+C14+C21 -> 100193.15 | D22: =+D14+D21 -> 111248.38 | E22: =+E14+E21 -> 100330.37 | F22: =+F14+F21 -> 105035.63 | G22: =+G14+G21 -> 114356.52 | H22: =+H14+H21 -> 110915.2 | I22: =+I14+I21 -> 114810.09 | J22: =+J14+J21 -> 119596.62 | ... N22: =+N14+N21 -> 111596.91 | O22: =+SUM(C22:N22) -> 1345628
B24: BALANCE DE ENERGÍA EN MWh - AÑO 2016
B26: DESCRIPCIÓN | C26: Enero | D26: Febrero | E26: Marzo | F26: Abril | G26: Mayo | H26: Junio | I26: Julio | J26: Agosto | K26: Septiembre | L26: Octubre | M26: Noviembre | N26: Diciembre | O26: Acumulado
B27: Energía producida | C27: =+C28+C29 -> 100193.15 | D27: =+D28+D29 -> 111248.38 | E27: =+E28+E29 -> 100330.37 | F27: =+F28+F29 -> 105035.63 | G27: =+G28+G29 -> 114356.52 | H27: =+H28+H29 -> 110915.2 | I27: =+I28+I29 -> 114810.09 | J27: =+J28+J29 -> 119596.62 | ... N27: =+N28+N29 -> 111596.91 | O27: =SUM(C27:N27) -> 1345628
B28: Hidroeléctrica | C28: =+C14 -> 61567.067 | D28: =+D14 -> 66408.16 | E28: =+E14 -> 62199.982 | F28: =+F14 -> 59417.911 | G28: =+G14 -> 61089.624 | H28: =+H14 -> 59430.512 | I28: =+I14 -> 61383.133 | J28: =+J14 -> 61280.807 | ... N28: =+N14 -> 64030.33 | O28: =SUM(C28:N28) -> 752493.94
B29: Termoeléctrica | C29: =+C21 -> 38626.082 | D29: =+D21 -> 44840.218 | E29: =+E21 -> 38130.39 | F29: =+F21 -> 45617.716 | G29: =+G21 -> 53266.895 | H29: =+H21 -> 51484.687 | I29: =+I21 -> 53426.96 | J29: =+J21 -> 58315.816 | ... N29: =+N21 -> 47566.58 | O29: =SUM(C29:N29) -> 593134.06
B30: Compra de energía | C30: =+C31 -> 0 | D30: =+D31 -> 0 | E30: =+E31 -> 0 | F30: =+F31 -> 0 | G30: =+G31 -> 0 | H30: =+H31 -> 0 | I30: =+I31 -> 0 | J30: =+J31 -> 0 | ... N30: =+N31 -> 0 | O30: =SUM(C30:N30) -> 0
B31: COES | C31: 0 | D31: 0 | E31: 0 | F31: 0 | G31: 0 | H31: 0 | I31: 0 | J31: 0 | K31: 0 | L31: 0 | M31: 0 | N31: 0 | O31: =SUM(C31:N31) -> 0
B32: Consumo propio de centrales | C32: =+C33+C34 -> 828.19244 | D32: =+D33+D34 -> 724.68752 | E32: =+E33+E34 -> 479.02384 | F32: =+F33+F34 -> 508.52441 | G32: =+G33+G34 -> 710.26335 | H32: =+H33+H34 -> 793.18931 | I32: =+I33+I34 -> 808.26003 | J32: =+J33+J34 -> 958.30577 | ... N32: =+N33+N34 -> 647.67077 | O32: =SUM(C32:N32) -> 8880.9936
B33: Hidroeléctrica | C33: 299.46542 | D33: 284.22147 | E33: 285.79649 | F33: 288.87511 | G33: 300.9717 | H33: 298.59112 | I33: 316.58368 | J33: 317.9686 | K33: 305.51325 | L33: 318.41516 | M33: 298.42689 | N33: 311.25935 | O33: =SUM(C33:N33) -> 3626.0882
B34: Termoeléctrica | C34: 528.72702 | D34: 440.46605 | E34: 193.22735 | F34: 219.6493 | G34: 409.29165 | H34: 494.59819 | I34: 491.67635 | J34: 640.33717 | K34: 549.56921 | L34: 312.68727 | M34: 638.26436 | N34: 336.41142 | O34: =SUM(C34:N34) -> 5254.9053
B35: Pérdidas Sistemas Transmisión | C35: =+C36+C37 -> 1464.8406 | D35: =+D36+D37 -> 1505.3921 | E35: =+E36+E37 -> 1484.6567 | F35: =+F36+F37 -> 1623.4725 | G35: =+G36+G37 -> 1659.0197 | H35: =+H36+H37 -> 1533.8382 | I35: =+I36+I37 -> 1521.3792 | J35: =+J36+J37 -> 1779.6095 | ... N35: =+N36+N37 -> 1541.1865 | O35: =SUM(C35:N35) -> 18997.521
B36: En muy alta tensión | C36: 585.93623 | D36: 602.15683 | E36: 593.86269 | F36: 649.38902 | G36: 663.60789 | H36: 613.53529 | I36: 608.55169 | J36: 711.84378 | K36: 641.93214 | L36: 652.34887 | M36: 659.36917 | N36: 616.47461 | O36: =SUM(C36:N36) -> 7599.0082
B37: En alta tensión | C37: 878.90435 | D37: 903.23525 | E37: 890.79404 | F37: 974.08353 | G37: 995.41183 | H37: 920.30293 | I37: 912.82753 | J37: 1067.7657 | K37: 962.8982 | L37: 978.5233 | M37: 989.05376 | N37: 924.71192 | O37: =SUM(C37:N37) -> 11398.512
B38: Energía total disponible | C38: =+C27+C30-C32-C35 -> 97900.115 | D38: =+D27+D30-D32-D35 -> 109018.3 | E38: =+E27+E30-E32-E35 -> 98366.691 | F38: =+F27+F30-F32-F35 -> 102903.63 | G38: =+G27+G30-G32-G35 -> 111987.24 | H38: =+H27+H30-H32-H35 -> 108588.17 | I38: =+I27+I30-I32-I35 -> 112480.45 | J38: =+J27+J30-J32-J35 -> 116858.71 | ... N38: =+N27+N30-N32-N35 -> 109408.05 | O38: =SUM(C38:N38) -> 1317749.5
B39: Venta de energía | C39: =+C40+C43+C53 -> 97900.115 | D39: =+D40+D43+D53 -> 109018.3 | E39: =+E40+E43+E53 -> 98366.691 | F39: =+F40+F43+F53 -> 102903.63 | G39: =+G40+G43+G53 -> 111987.24 | H39: =+H40+H43+H53 -> 108588.17 | I39: =+I40+I43+I53 -> 112480.45 | J39: =+J40+J43+J53 -> 116858.71 | ... N39: =+N40+N43+N53 -> 109408.05 | O39: =SUM(C39:N39) -> 1317749.5
B40: A Emp. Generadoras | C40: =+C41+C42 -> 26081.763 | D40: =+D41+D42 -> 39723.074 | E40: =+E41+E42 -> 28203.448 | F40: =+F41+F42 -> 35341.813 | G40: =+G41+G42 -> 43647.145 | H40: =+H41+H42 -> 43532.293 | I40: =+I41+I42 -> 46252.634 | J40: =+J41+J42 -> 49007.1 | ... N40: =+N41+N42 -> 41527.679 | O40: =SUM(C40:N40) -> 506477.14
B41: COES | C41: 26081.763 | D41: 39723.074 | E41: 28203.448 | F41: 35341.813 | G41: 43647.145 | H41: 43532.293 | I41: 46252.634 | J41: 49007.1 | K41: 47106.387 | L41: 52500.203 | M41: 53553.601 | N41: 41527.679 | O41: =SUM(C41:N41) -> 506477.14
B42: Electroperú (SWAP) | C42: 0 | D42: 0 | E42: 0 | F42: 0 | G42: 0 | H42: 0 | I42: 0 | J42: 0 | K42: 0 | L42: 0 | M42: 0 | O42: =SUM(C42:N42) -> 0
B43: A emp. Distribuidoras: | C43: =SUM(C44:C52) -> 71124.379 | D43: =SUM(D44:D52) -> 68489.157 | E43: =SUM(E44:E52) -> 69339.989 | F43: =SUM(F44:F52) -> 66755.886 | G43: =SUM(G44:G52) -> 67413.699 | H43: =SUM(H44:H52) -> 64187.6 | I43: =SUM(I44:I52) -> 65281.066 | J43: =SUM(J44:J52) -> 66869.162 | ... N43: =SUM(N44:N52) -> 65712.746 | O43: =SUM(C43:N43) -> 799378.73
B44: Edelnor | C44: 13642.554 | D44: 13378.521 | E44: 13377.868 | F44: 12758.429 | G44: 12889.447 | H44: 11900.284 | I44: 12504.08 | J44: 12559.827 | K44: 12248.36 | L44: 12425.68 | M44: 11995.583 | N44: 12860.65 | O44: =SUM(C44:N44) -> 152541.28
B45: Luz del Sur | C45: 48522.058 | D45: 47162.769 | E45: 47750.361 | F45: 45938.621 | G45: 45994.086 | H45: 43408.443 | I45: 43648.555 | J45: 45003.718 | K45: 44058.722 | L45: 44786.867 | M45: 43397.986 | N45: 44576.271 | O45: =SUM(C45:N45) -> 544248.46
...

Sheet 2017
C3: PRODUCCIÓN MENSUAL DE ENERGÍA ELÉCTRICA EN EGASA
C4: AÑO 2017 (MWh)
C6: CENTRALES | D6: Enero | E6: Febrero | F6: Marzo | G6: Abril | H6: Mayo | I6: Junio | J6: Julio | K6: Agosto | L6: Septiembre | M6: Octubre | N6: Noviembre | O6: Diciembre | P6: Acumulado
C7: Hidráulica
C8: Charcani I | D8: 1131.6971 | E8: 914.19372 | F8: 505.61345 | G8: 944.25365 | H8: 1227.7596 | I8: 1202.2403 | J8: 1235.1516 | K8: 1230.5896 | L8: 1183.1837 | M8: 1216.7963 | N8: 1187.2042 | O8: 1251.6718 | P8: =+SUM(D8:O8) -> 13230.355
C9: Charcani II | D9: 404.73452 | E9: 336.87828 | F9: 327.47807 | G9: 381.87174 | H9: 420.97334 | I9: 413.60733 | J9: 418.39151 | K9: 427.37558 | L9: 412.9533 | M9: 421.47836 | N9: 412.4977 | O9: 425.81247 | P9: =+SUM(D9:O9) -> 4804.0522
C10: Charcani III | D10: 3164.3521 | E10: 2773.7265 | F10: 2575.2854 | G10: 2829.559 | H10: 3338.7908 | I10: 3218.1126 | J10: 3369.2486 | K10: 3347.609 | L10: 3274.419 | M10: 3340.67 | N10: 3241.3551 | O10: 3359.3087 | P10: =+SUM(D10:O10) -> 37832.437
C11: Charcani IV | D11: 7358.1597 | E11: 6429.6375 | F11: 6143.83 | G11: 9510.1653 | H11: 8125.0136 | I11: 7969.1913 | J11: 8614.8832 | K11: 8700.8902 | L11: 9202.4403 | M11: 9507.6287 | N11: 9149.1548 | O11: 9418.4096 | P11: =+SUM(D11:O11) -> 100129.4
C12: Charcani V | D12: 44993.963 | E12: 40649.44 | F12: 43714.557 | G12: 66287.283 | H12: 49329.039 | I12: 47392.87 | J12: 53425.856 | K12: 53423 | L12: 56007.731 | M12: 57878.946 | N12: 56010.855 | O12: 57899.012 | P12: =+SUM(D12:O12) -> 627012.55
C13: Charcani VI | D13: 4089.3769 | E13: 3380.5336 | F13: 3716.264 | G13: 5029.652 | H13: 4767.6958 | I13: 4657.1431 | J13: 5335.1314 | K13: 5340.779 | L13: 5405.8122 | M13: 5808.1043 | N13: 5052.4007 | O13: 5803.1061 | P13: =+SUM(D13:O13) -> 58385.999
C14: Total Hidraúlica | D14: =SUM(D8:D13) -> 61142.283 | E14: =SUM(E8:E13) -> 54484.409 | F14: =SUM(F8:F13) -> 56983.028 | G14: =SUM(G8:G13) -> 84982.785 | H14: =SUM(H8:H13) -> 67209.272 | I14: =SUM(I8:I13) -> 64853.164 | J14: =SUM(J8:J13) -> 72398.663 | K14: =SUM(K8:K13) -> 72470.243 | ... O14: =SUM(O8:O13) -> 78157.321 | P14: =+SUM(D14:O14) -> 841394.8
C15: Térmica
C16: T.Vapor | D16: 0 | E16: 0 | F16: 0 | G16: 0 | H16: 0 | I16: 0 | J16: 0 | K16: 0 | L16: 0 | M16: 0 | N16: 0 | O16: 0 | P16: =+SUM(D16:O16) -> 0
C17: T.G.-Ciclo Combinado | D17: 11.521423 | E17: 102.89407 | F17: 0 | G17: 0 | H17: 0 | I17: 0 | J17: 0 | K17: 0 | L17: 0 | M17: 0 | N17: 0 | O17: 0 | P17: =+SUM(D17:O17) -> 114.41549
C18: Sulzers | D18: 701.38252 | E18: 4552.8757 | F18: 3140.7568 | G18: 662.34038 | H18: 5715.1801 | I18: 3761.4463 | J18: 3836.0574 | K18: 4949.569 | L18: 4231.9094 | M18: 1336.9326 | N18: 9.0435825 | O18: 0 | P18: =+SUM(D18:O18) -> 32897.494
C19: C.T. Mollendo | D19: 1338.8287 | E19: 1483.0366 | F19: 2141.9592 | G19: 517.03764 | H19: 6634.3076 | I19: 2702.6777 | J19: 3860.8097 | K19: 2968.5403 | L19: 6470.4783 | M19: 770.84478 | N19: 202.8605 | O19: 0 | P19: =+SUM(D19:O19) -> 29091.381
C20: C.T. Pisco | D20: 35832.495 | E20: 25329.233 | F20: 33050.704 | G20: 28109.256 | H20: 42951.487 | I20: 49800.828 | J20: 53082.504 | K20: 52230.597 | L20: 34196.315 | M20: 50020.208 | N20: 47598.942 | O20: 49422.494 | P20: =+SUM(D20:O20) -> 501625.06
C21: Total Térmica | D21: =SUM(D16:D20) -> 37884.227 | E21: =SUM(E16:E20) -> 31468.039 | F21: =SUM(F16:F20) -> 38333.421 | G21: =SUM(G16:G20) -> 29288.634 | H21: =SUM(H16:H20) -> 55300.974 | I21: =SUM(I16:I20) -> 56264.952 | J21: =SUM(J16:J20) -> 60779.371 | K21: =SUM(K16:K20) -> 60148.706 | ... O21: =SUM(O16:O20) -> 49422.494 | P21: =+SUM(D21:O21) -> 563728.35
C22: TOTAL EGASA | D22: =+D14+D21 -> 99026.51 | E22: =+E14+E21 -> 85952.449 | F22: =+F14+F21 -> 95316.449 | G22: =+G14+G21 -> 114271.42 | H22: =+H14+H21 -> 122510.25 | I22: =+I14+I21 -> 121118.12 | J22: =+J14+J21 -> 133178.03 | K22: =+K14+K21 -> 132618.95 | ... O22: =+O14+O21 -> 127579.82 | P22: =+SUM(D22:O22) -> 1405123.2
Q23: 1000
C24: BALANCE DE ENERGÍA EN MWh - AÑO 2017
C26: DESCRIPCIÓN | D26: Enero | E26: Febrero | F26: Marzo | G26: Abril | H26: Mayo | I26: Junio | J26: Julio | K26: Agosto | L26: Septiembre | M26: Octubre | N26: Noviembre | O26: Diciembre | P26: Acumulado
C27: Energía producida | D27: =+D28+D29 -> 99026.51 | E27: =+E28+E29 -> 85952.449 | F27: =+F28+F29 -> 95316.449 | G27: =+G28+G29 -> 114271.42 | H27: =+H28+H29 -> 122510.25 | I27: =+I28+I29 -> 121118.12 | J27: =+J28+J29 -> 133178.03 | K27: =+K28+K29 -> 132618.95 | ... O27: =+O28+O29 -> 127579.82 | P27: =SUM(D27:O27) -> 1405123.2
C28: Hidroeléctrica | D28: =+D14 -> 61142.283 | E28: 54484.409 | F28: 56983.028 | G28: 84982.785 | H28: 67209.272 | I28: 64853.164 | J28: 72398.663 | K28: 72470.243 | L28: 75486.539 | M28: 78173.624 | N28: 75053.467 | O28: 78157.321 | P28: =SUM(D28:O28) -> 841394.8
C29: Termoeléctrica | D29: =+D21 -> 37884.227 | E29: 31468.039 | F29: 38333.421 | G29: 29288.634 | H29: 55300.974 | I29: 56264.952 | J29: 60779.371 | K29: 60148.706 | L29: 44898.703 | M29: 52127.985 | N29: 47810.846 | O29: 49422.494 | P29: =SUM(D29:O29) -> 563728.35
C30: Compra de energía | D30: =+D31 -> 0 | E30: =+E31 -> 0 | F30: =+F31 -> 0 | G30: =+G31 -> 0 | H30: =+H31 -> 0 | I30: =+I31 -> 0 | J30: =+J31 -> 0 | K30: =+K31 -> 0 | ... O30: =+O31 -> 0 | P30: =SUM(D30:O30) -> 0
C31: COES | D31: 0 | E31: 0 | F31: 0 | G31: 0 | H31: 0 | I31: 0 | J31: 0 | K31: 0 | L31: 0 | M31: 0 | P31: =SUM(D31:O31) -> 0
C32: Consumo propio de centrales | D32: =+D33+D34 -> 577.77153 | E32: =+E33+E34 -> 749.33384 | F32: =+F33+F34 -> 714.08569 | G32: =+G33+G34 -> 463.39152 | H32: =+H33+H34 -> 1153.8461 | I32: =+I33+I34 -> 883.06092 | J32: =+J33+J34 -> 989.60583 | K32: =+K33+K34 -> 1090.7572 | ... O32: =+O33+O34 -> 496.19404 | P32: =SUM(D32:O32) -> 9126.7927
C33: Hidroeléctrica | D33: 323.39033 | E33: 285.10255 | F33: 222.03207 | G33: 273.87732 | H33: 313.07544 | I33: 308.26231 | J33: 306.54787 | K33: =+K83/1000 -> 303.78866 | L33: 298.25999 | M33: 304.89975 | N33: 296.39112 | O33: 304.11797 | P33: =SUM(D33:O33) -> 3539.7454
C34: Termoeléctrica | D34: 254.3812 | E34: 464.23129 | F34: 492.05362 | G34: 189.5142 | H34: 840.77068 | I34: 574.79861 | J34: 683.05796 | K34: =+K92/1000 -> 786.96854 | L34: 551.80792 | M34: 350.61766 | N34: 206.76957 | O34: 192.07607 | P34: =SUM(D34:O34) -> 5587.0473
C35: Pérdidas Sistemas Transmisión | D35: =+D36+D37 -> 1440.4882 | E35: =+E36+E37 -> 1197.3389 | F35: =+F36+F37 -> 1283.2811 | G35: =+G36+G37 -> 1429.5567 | H35: =+H36+H37 -> 1602.683 | I35: =+I36+I37 -> 1525.2077 | J35: =+J36+J37 -> 1596.717 | K35: =+K36+K37 -> 1477.3707 | ... O35: =+O36+O37 -> 1162.8164 | P35: =SUM(D35:O35) -> 17170.615
C36: En muy alta tensión | D36: 576.19529 | E36: 478.93557 | F36: 513.31246 | G36: 571.82268 | H36: 641.07321 | I36: 610.0831 | J36: 638.68681 | K36: 590.94829 | L36: 645.66206 | M36: 586.93949 | N36: 549.46031 | O36: 465.12655 | P36: =SUM(D36:O36) -> 6868.2458
C37: En alta tensión | D37: 864.29294 | E37: 718.40336 | F37: 769.96869 | G37: 857.73402 | H37: 961.60982 | I37: 915.12464 | J37: 958.03021 | K37: 886.42243 | L37: 968.49308 | M37: 880.40923 | N37: 824.19047 | O37: 697.68982 | P37: =SUM(D37:O37) -> 10302.369
C38: Energía total disponible | D38: =+D27+D30-D32-D35 -> 97008.251 | E38: =+E27+E30-E32-E35 -> 84005.776 | F38: =+F27+F30-F32-F35 -> 93319.082 | G38: =+G27+G30-G32-G35 -> 112378.47 | H38: =+H27+H30-H32-H35 -> 119753.72 | I38: =+I27+I30-I32-I35 -> 118709.85 | J38: =+J27+J30-J32-J35 -> 130591.71 | K38: =+K27+K30-K32-K35 -> 130050.82 | ... O38: =+O27+O30-O32-O35 -> 125920.8 | P38: =SUM(D38:O38) -> 1378825.7
C39: Venta de energía | D39: =+D40+D43+D53 -> 97008.251 | E39: =+E40+E43+E53 -> 84005.776 | F39: =+F40+F43+F53 -> 93319.082 | G39: =+G40+G43+G53 -> 112378.47 | H39: =+H40+H43+H53 -> 119753.72 | I39: =+I40+I43+I53 -> 118709.85 | J39: =+J40+J43+J53 -> 130591.71 | K39: =+K40+K43+K53 -> 130050.82 | ... O39: =+O40+O43+O53 -> 125920.8 | P39: =SUM(D39:O39) -> 1378825.7
C40: A Emp. Generadoras | D40: =+D41+D42 -> 29272.657 | E40: =+E41+E42 -> 19489.25 | F40: =+F41+F42 -> 22711.859 | G40: =+G41+G42 -> 46974.932 | H40: =+H41+H42 -> 53403.568 | I40: =+I41+I42 -> 55895.141 | J40: =+J41+J42 -> 67141.65 | K40: =+K41+K42 -> 65521.447 | ... O40: =+O41+O42 -> 62624.172 | P40: =SUM(D40:O40) -> 601775.5 | R40: =+H35-R38 -> 1602.683
C41: COES | D41: 29272.657 | E41: 19489.25 | F41: 22711.859 | G41: 46974.932 | H41: 53403.568 | I41: 55895.141 | J41: 67141.65 | K41: 65521.447 | L41: 54886.926 | M41: 64405.112 | N41: 59448.79 | O41: 62624.172 | P41: =SUM(D41:O41) -> 601775.5
C42: Electroperú (SWAP) | D42: 0 | E42: 0 | F42: 0 | G42: 0 | H42: 0 | I42: 0 | J42: 0 | K42: 0 | L42: 0 | M42: 0 | N42: 0 | P42: =SUM(D42:O42) -> 0
C43: A emp. Distribuidoras: | D43: =SUM(D44:D52) -> 65811.09 | E43: =SUM(E44:E52) -> 62374.744 | F43: =SUM(F44:F52) -> 68078.409 | G43: =SUM(G44:G52) -> 62932.901 | H43: =(SUM(H44:H52)) -> 63751.12 | I43: =SUM(I44:I52) -> 60092.32 | J43: =SUM(J44:J52) -> 61088.623 | K43: =SUM(K44:K52) -> 62096.121 | L43: =SUM(L44:L52) -> 60457.349 | M43: =SUM(M44:M52) -> 61036.383 | N43: =SUM(N44:N52) -> 58888.856 | O43: =SUM(O44:O52) -> 60752.804 | P43: =SUM(D43:O43) -> 747360.72
C44: Edelnor | D44: 12538.446 | E44: 11744.085 | F44: 12472.109 | G44: 11537.996 | H44: 11933.225 | I44: 11142.879 | J44: 11718.093 | K44: 11885.653 | L44: 11737.945 | M44: 11966.413 | N44: 11382.165 | O44: 12090.232 | P44: =SUM(D44:O44) -> 142149.24
...

Sheet 2018
C3: PRODUCCIÓN MENSUAL DE ENERGÍA ELÉCTRICA EN EGASA
C4: AÑO 2017 (MWh)
C6: CENTRALES | D6: Enero | E6: Febrero | F6: Marzo | G6: Abril | H6: Mayo | I6: Junio | J6: Julio | K6: Agosto | L6: Septiembre | M6: Octubre | N6: Noviembre | O6: Diciembre | P6: Acumulado
C7: Hidráulica
C8: Charcani I | D8: 1131.6971 | P8: =+SUM(D8:O8) -> 1131.6971
C9: Charcani II | D9: 404.73452 | P9: =+SUM(D9:O9) -> 404.73452
C10: Charcani III | D10: 3164.3521 | P10: =+SUM(D10:O10) -> 3164.3521
C11: Charcani IV | D11: 7358.1597 | P11: =+SUM(D11:O11) -> 7358.1597
C12: Charcani V | D12: 44993.963 | P12: =+SUM(D12:O12) -> 44993.963
C13: Charcani VI | D13: 4089.3769 | P13: =+SUM(D13:O13) -> 4089.3769
C14: Total Hidraúlica | D14: =SUM(D8:D13) -> 61142.283 | E14: =SUM(E8:E13) -> 0 | F14: =SUM(F8:F13) -> 0 | G14: =SUM(G8:G13) -> 0 | H14: =SUM(H8:H13) -> 0 | I14: =SUM(I8:I13) -> 0 | J14: =SUM(J8:J13) -> 0 | K14: =SUM(K8:K13) -> 0 | ... O14: =SUM(O8:O13) -> 0 | P14: =+SUM(D14:O14) -> 61142.283
C15: Térmica
C16: T.Vapor | D16: 0 | P16: =+SUM(D16:O16) -> 0
C17: T.G.-Ciclo Combinado | D17: 11.521423 | P17: =+SUM(D17:O17) -> 11.521423
C18: Sulzers | D18: 701.38252 | P18: =+SUM(D18:O18) -> 701.38252
C19: C.T. Mollendo | D19: 1338.8287 | P19: =+SUM(D19:O19) -> 1338.8287
C20: C.T. Pisco | D20: 35832.495 | P20: =+SUM(D20:O20) -> 35832.495
C21: Total Térmica | D21: =SUM(D16:D20) -> 37884.227 | E21: =SUM(E16:E20) -> 0 | F21: =SUM(F16:F20) -> 0 | G21: =SUM(G16:G20) -> 0 | H21: =SUM(H16:H20) -> 0 | I21: =SUM(I16:I20) -> 0 | J21: =SUM(J16:J20) -> 0 | K21: =SUM(K16:K20) -> 0 | ... O21: =SUM(O16:O20) -> 0 | P21: =+SUM(D21:O21) -> 37884.227
C22: TOTAL EGASA | D22: =+D14+D21 -> 99026.51 | E22: =+E14+E21 -> 0 | F22: =+F14+F21 -> 0 | G22: =+G14+G21 -> 0 | H22: =+H14+H21 -> 0 | I22: =+I14+I21 -> 0 | J22: =+J14+J21 -> 0 | K22: =+K14+K21 -> 0 | ... O22: =+O14+O21 -> 0 | P22: =+SUM(D22:O22) -> 99026.51
Q23: 1000
C24: BALANCE DE ENERGÍA EN MWh - AÑO 2018
C26: DESCRIPCIÓN | D26: Enero | E26: Febrero | F26: Marzo | G26: Abril | H26: Mayo | I26: Junio | J26: Julio | K26: Agosto | L26: Septiembre | M26: Octubre | N26: Noviembre | O26: Diciembre | P26: Acumulado
C27: Energía producida | D27: =+D28+D29 -> 116590.34 | E27: =+E28+E29 -> 102739.3 | F27: =+F28+F29 -> 115111.37 | G27: =+G28+G29 -> 86446.789 | H27: =+H28+H29 -> 73820.186 | I27: =+I28+I29 -> 70980.624 | J27: =+J28+J29 -> 75723.573 | K27: =+K28+K29 -> 75196.366 | ... O27: =+O28+O29 -> 91081.007 | P27: =SUM(D27:O27) -> 1041584
C28: Hidroeléctrica | D28: 89076.605 | E28: 91831.452 | F28: 108580.26 | G28: 82397.809 | H28: 67084.678 | I28: 67034.988 | J28: 74143.988 | K28: 73728.608 | L28: 70018.542 | M28: 78763.008 | N28: =74636334.9403163/1000 -> 74636.335 | O28: 78264.531 | P28: =SUM(D28:O28) -> 955560.81
C29: Termoeléctrica | D29: 27513.735 | E29: 10907.846 | F29: 6531.1074 | G29: 4048.9795 | H29: 6735.5071 | I29: 3945.6362 | J29: 1579.5853 | K29: 1467.7571 | L29: 793.22606 | M29: 1359.4774 | N29: =8323907.8109382/1000 -> 8323.9078 | O29: 12816.476 | P29: =SUM(D29:O29) -> 86023.241
C30: Compra de energía | D30: =+D31 -> 0 | E30: =+E31 -> 0 | F30: =+F31 -> 0 | G30: =+G31 -> 0 | H30: =+H31 -> 0 | I30: =+I31 -> 0 | J30: =+J31 -> 4111.8636 | K30: =+K31 -> 1905.4541 | ... O30: =+O31 -> 0 | P30: =SUM(D30:O30) -> 7679.3483
C31: COES | D31: 0 | E31: 0 | F31: 0 | G31: 0 | H31: 0 | I31: 0 | J31: 4111.8636 | K31: 1905.4541 | L31: 0 | M31: 1662.0306 | N31: 0 | P31: =SUM(D31:O31) -> 7679.3483
C32: Consumo propio de centrales | D32: =+D33+D34 -> 425.41875 | E32: =+E33+E34 -> 392.10484 | F32: =+F33+F34 -> 367.90234 | G32: =+G33+G34 -> 330.86296 | H32: =+H33+H34 -> 332.21455 | I32: =+I33+I34 -> 497.07396 | J32: =+J33+J34 -> 461.66019 | K32: =+K33+K34 -> 319.34972 | ... O32: =+O33+O34 -> 321.19504 | P32: =SUM(D32:O32) -> 4391.4736
C33: Hidroeléctrica | D33: 319.19512 | E33: 304.26569 | F33: 343.00388 | G33: 314.31736 | H33: 304.53582 | I33: 304.33451 | J33: 310.33159 | K33: 302.5947 | L33: 299.11276 | M33: 307.57254 | N33: 295.35651 | O33: =289.454726041317-5.79740113270283 -> 283.65732 | P33: =SUM(D33:O33) -> 3688.2778
C34: Termoeléctrica | D34: 106.22363 | E34: 87.839149 | F34: 24.898467 | G34: 16.545597 | H34: 27.67873 | I34: 192.73945 | J34: 151.3286 | K34: 16.755024 | L34: 3.2110245 | M34: 3.8782018 | N34: 34.560249 | O34: 37.537713 | P34: =SUM(D34:O34) -> 703.19584
C35: Pérdidas Sistemas Transmisión | D35: =+D36+D37 -> 1513.918 | E35: =+E36+E37 -> 1308.8409 | F35: =+F36+F37 -> 895.09963 | G35: =+G36+G37 -> 1267.1498 | H35: =+H36+H37 -> 1122.7229 | I35: =+I36+I37 -> 881.15667 | J35: =+J36+J37 -> 503.51932 | K35: =+K36+K37 -> 946.38392 | ... O35: =+O36+O37 -> 1112.4926 | P35: =SUM(D35:O35) -> 14987.621
C36: En muy alta tensión | D36: 605.56719 | E36: 523.53636 | F36: 358.03985 | G36: 506.85992 | H36: 449.08916 | I36: 352.46267 | J36: 201.40773 | K36: 378.55357 | L36: 360.48576 | M36: 836.87701 | N36: 977.17205 | O36: 444.99703 | P36: =SUM(D36:O36) -> 5995.0483
C37: En alta tensión | D37: 908.35079 | E37: 785.30453 | F37: 537.05978 | G37: 760.28988 | H37: 673.63374 | I37: 528.694 | J37: 302.11159 | K37: 567.83035 | L37: 540.72865 | M37: 1255.3155 | N37: 1465.7581 | O37: 667.49555 | P37: =SUM(D37:O37) -> 8992.5725
C38: Energía total disponible | D38: =+D27+D30-D32-D35 -> 114651 | E38: =+E27+E30-E32-E35 -> 101038.35 | F38: =+F27+F30-F32-F35 -> 113848.37 | G38: =+G27+G30-G32-G35 -> 84848.776 | H38: =+H27+H30-H32-H35 -> 72365.248 | I38: =+I27+I30-I32-I35 -> 69602.393 | J38: =+J27+J30-J32-J35 -> 78870.257 | K38: =+K27+K30-K32-K35 -> 75836.086 | ... O38: =+O27+O30-O32-O35 -> 89647.319 | P38: =SUM(D38:O38) -> 1029884.3
C39: Venta de energía | D39: =+D40+D43+D54 -> 114651 | E39: =+E40+E43+E54 -> 101038.35 | F39: =+F40+F43+F54 -> 113848.37 | G39: =+G40+G43+G54 -> 84848.776 | H39: =+H40+H43+H54 -> 72365.248 | I39: =+I40+I43+I54 -> 69602.393 | J39: =+J40+J43+J54 -> 78870.257 | K39: =+K40+K43+K54 -> 75836.086 | ... O39: =+O40+O43+O54 -> 89647.319 | P39: =SUM(D39:O39) -> 1029884.3
C40: A Emp. Generadoras | D40: =+D41+D42 -> 56927.84 | E40: =+E41+E42 -> 46159.398 | F40: =+F41+F42 -> 55089.721 | G40: =+G41+G42 -> 26944.745 | H40: =+H41+H42 -> 14637.573 | I40: =+I41+I42 -> 14444.374 | J40: =+J41+J42 -> 22422.158 | K40: =+K41+K42 -> 19364.859 | ... O40: =+O41+O42 -> 32152.651 | P40: =SUM(D40:O40) -> 350450.71
C41: COES | D41: 56927.84 | E41: 46159.398 | F41: 55089.721 | G41: 26944.745 | H41: 14637.573 | I41: 14444.374 | J41: 22422.158 | K41: 19364.859 | L41: 14685.295 | M41: 23227.62 | N41: 24394.476 | O41: 32152.651 | P41: =SUM(D41:O41) -> 350450.71
C42: Electroperú (SWAP) | D42: 0 | E42: 0 | F42: 0 | G42: 0 | H42: 0 | I42: 0 | J42: 0 | K42: 0 | L42: 0 | M42: 0 | N42: 0 | P42: =SUM(D42:O42) -> 0
C43: A emp. Distribuidoras: | D43: =SUM(D44:D52) -> 54830.9 | E43: =SUM(E44:E52) -> 52239.07 | F43: =SUM(F44:F52) -> 55735.654 | G43: =SUM(G44:G53) -> 55075.946 | H43: =SUM(H44:H53) -> 54587.342 | I43: =SUM(I44:I53) -> 52199.137 | J43: =SUM(J44:J53) -> 53331.173 | K43: =SUM(K44:K53) -> 53704.336 | L43: =SUM(L44:L53) -> 52262.628 | M43: =SUM(M44:M53) -> 53513.975 | N43: =SUM(N44:N53) -> 53176.671 | ... P43: =SUM(P44:P53) -> 645862.01
C44: Edelnor | D44: 12092.203 | E44: 11329.898 | F44: 12293.932 | G44: 11811.546 | H44: 11678.863 | I44: 11183.292 | J44: 11369.888 | K44: 11358.021 | L44: 10996.761 | M44: 11516.386 | N44: 11381.287 | O44: 11909.133 | P44: =SUM(D44:O44) -> 138921.21
...

Sheet 2018-R1
C3: PRODUCCIÓN MENSUAL DE ENERGÍA ELÉCTRICA EN EGASA
C4: AÑO 2017 (MWh)
C6: CENTRALES | D6: Enero | E6: Febrero | F6: Marzo | G6: Abril | H6: Mayo | I6: Junio | J6: Julio | K6: Agosto | L6: Septiembre | M6: Octubre | N6: Noviembre | O6: Diciembre | P6: Acumulado
C7: Hidráulica
C8: Charcani I | D8: 1131.6971 | P8: =+SUM(D8:O8) -> 1131.6971
C9: Charcani II | D9: 404.73452 | P9: =+SUM(D9:O9) -> 404.73452
C10: Charcani III | D10: 3164.3521 | P10: =+SUM(D10:O10) -> 3164.3521
C11: Charcani IV | D11: 7358.1597 | P11: =+SUM(D11:O11) -> 7358.1597
C12: Charcani V | D12: 44993.963 | P12: =+SUM(D12:O12) -> 44993.963
C13: Charcani VI | D13: 4089.3769 | P13: =+SUM(D13:O13) -> 4089.3769
C14: Total Hidraúlica | D14: =SUM(D8:D13) -> 61142.283 | E14: =SUM(E8:E13) -> 0 | F14: =SUM(F8:F13) -> 0 | G14: =SUM(G8:G13) -> 0 | H14: =SUM(H8:H13) -> 0 | I14: =SUM(I8:I13) -> 0 | J14: =SUM(J8:J13) -> 0 | K14: =SUM(K8:K13) -> 0 | ... O14: =SUM(O8:O13) -> 0 | P14: =+SUM(D14:O14) -> 61142.283
C15: Térmica
C16: T.Vapor | D16: 0 | P16: =+SUM(D16:O16) -> 0
C17: T.G.-Ciclo Combinado | D17: 11.521423 | P17: =+SUM(D17:O17) -> 11.521423
C18: Sulzers | D18: 701.38252 | P18: =+SUM(D18:O18) -> 701.38252
C19: C.T. Mollendo | D19: 1338.8287 | P19: =+SUM(D19:O19) -> 1338.8287
C20: C.T. Pisco | D20: 35832.495 | P20: =+SUM(D20:O20) -> 35832.495
C21: Total Térmica | D21: =SUM(D16:D20) -> 37884.227 | E21: =SUM(E16:E20) -> 0 | F21: =SUM(F16:F20) -> 0 | G21: =SUM(G16:G20) -> 0 | H21: =SUM(H16:H20) -> 0 | I21: =SUM(I16:I20) -> 0 | J21: =SUM(J16:J20) -> 0 | K21: =SUM(K16:K20) -> 0 | ... O21: =SUM(O16:O20) -> 0 | P21: =+SUM(D21:O21) -> 37884.227
C22: TOTAL EGASA | D22: =+D14+D21 -> 99026.51 | E22: =+E14+E21 -> 0 | F22: =+F14+F21 -> 0 | G22: =+G14+G21 -> 0 | H22: =+H14+H21 -> 0 | I22: =+I14+I21 -> 0 | J22: =+J14+J21 -> 0 | K22: =+K14+K21 -> 0 | ... O22: =+O14+O21 -> 0 | P22: =+SUM(D22:O22) -> 99026.51
Q23: 1000
C24: BALANCE DE ENERGÍA EN MWh - AÑO 2018
C26: DESCRIPCIÓN | D26: Enero | E26: Febrero | F26: Marzo | G26: Abril | H26: Mayo | I26: Junio | J26: Julio | K26: Agosto | L26: Septiembre | M26: Octubre | N26: Noviembre | O26: Diciembre | P26: Acumulado
C27: Energía producida | D27: =+D28+D29 -> 116590.34 | E27: =+E28+E29 -> 102739.3 | F27: =+F28+F29 -> 115111.37 | G27: =+G28+G29 -> 86446.789 | H27: =+H28+H29 -> 73820.186 | I27: =+I28+I29 -> 70980.624 | J27: =+J28+J29 -> 75723.573 | K27: =+K28+K29 -> 75196.366 | ... O27: =+O28+O29 -> 91081.007 | P27: =SUM(D27:O27) -> 1041584
C28: Hidroeléctrica | D28: 89076.605 | E28: 91831.452 | F28: 108580.26 | G28: 82397.809 | H28: 67084.678 | I28: 67034.988 | J28: 74143.988 | K28: 73728.608 | L28: 70018.542 | M28: 78763.008 | N28: =74636334.9403163/1000 -> 74636.335 | O28: 78264.531 | P28: =SUM(D28:O28) -> 955560.81
C29: Termoeléctrica | D29: 27513.735 | E29: 10907.846 | F29: 6531.1074 | G29: 4048.9795 | H29: 6735.5071 | I29: 3945.6362 | J29: 1579.5853 | K29: 1467.7571 | L29: 793.22606 | M29: 1359.4774 | N29: =8323907.8109382/1000 -> 8323.9078 | O29: 12816.476 | P29: =SUM(D29:O29) -> 86023.241
C30: Compra de energía | D30: =+D31 -> 0 | E30: =+E31 -> 0 | F30: =+F31 -> 0 | G30: =+G31 -> 0 | H30: =+H31 -> 0 | I30: =+I31 -> 0 | J30: =+J31 -> 4111.8636 | K30: =+K31 -> 1905.4541 | ... O30: =+O31 -> 0 | P30: =SUM(D30:O30) -> 7679.3483
C31: COES | D31: 0 | E31: 0 | F31: 0 | G31: 0 | H31: 0 | I31: 0 | J31: 4111.8636 | K31: 1905.4541 | L31: 0 | M31: 1662.0306 | N31: 0 | P31: =SUM(D31:O31) -> 7679.3483
C32: Consumo propio de centrales | D32: =+D33+D34 -> 425.41875 | E32: =+E33+E34 -> 392.10484 | F32: =+F33+F34 -> 367.90234 | G32: =+G33+G34 -> 330.86296 | H32: =+H33+H34 -> 332.21455 | I32: =+I33+I34 -> 497.07396 | J32: =+J33+J34 -> 461.66019 | K32: =+K33+K34 -> 319.34972 | ... O32: =+O33+O34 -> 321.19504 | P32: =SUM(D32:O32) -> 4391.4736
C33: Hidroeléctrica | D33: 319.19512 | E33: 304.26569 | F33: 343.00388 | G33: 314.31736 | H33: 304.53582 | I33: 304.33451 | J33: 310.33159 | K33: 302.5947 | L33: 299.11276 | M33: 307.57254 | N33: 295.35651 | O33: =289.454726041317-5.79740113270283 -> 283.65732 | P33: =SUM(D33:O33) -> 3688.2778
C34: Termoeléctrica | D34: 106.22363 | E34: 87.839149 | F34: 24.898467 | G34: 16.545597 | H34: 27.67873 | I34: 192.73945 | J34: 151.3286 | K34: 16.755024 | L34: 3.2110245 | M34: 3.8782018 | N34: 34.560249 | O34: 37.537713 | P34: =SUM(D34:O34) -> 703.19584
C35: Pérdidas Sistemas Transmisión | D35: =+D36+D37 -> 1513.918 | E35: =+E36+E37 -> 1308.8409 | F35: =+F36+F37 -> 895.09963 | G35: =+G36+G37 -> 1267.1498 | H35: =+H36+H37 -> 1122.7229 | I35: =+I36+I37 -> 881.15667 | J35: =+J36+J37 -> 503.51932 | K35: =+K36+K37 -> 946.38392 | ... O35: =+O36+O37 -> 1105.1254 | P35: =SUM(D35:O35) -> 14980.254
C36: En muy alta tensión | D36: 605.56719 | E36: 523.53636 | F36: 358.03985 | G36: 506.85992 | H36: 449.08916 | I36: 352.46267 | J36: 201.40773 | K36: 378.55357 | L36: 360.48576 | M36: 836.87701 | N36: 977.17205 | O36: 442.05015 | P36: =SUM(D36:O36) -> 5992.1014
C37: En alta tensión | D37: 908.35079 | E37: 785.30453 | F37: 537.05978 | G37: 760.28988 | H37: 673.63374 | I37: 528.694 | J37: 302.11159 | K37: 567.83035 | L37: 540.72865 | M37: 1255.3155 | N37: 1465.7581 | O37: 663.07522 | P37: =SUM(D37:O37) -> 8988.1521
C38: Energía total disponible | D38: =+D27+D30-D32-D35 -> 114651 | E38: =+E27+E30-E32-E35 -> 101038.35 | F38: =+F27+F30-F32-F35 -> 113848.37 | G38: =+G27+G30-G32-G35 -> 84848.776 | H38: =+H27+H30-H32-H35 -> 72365.248 | I38: =+I27+I30-I32-I35 -> 69602.393 | J38: =+J27+J30-J32-J35 -> 78870.257 | K38: =+K27+K30-K32-K35 -> 75836.086 | ... O38: =+O27+O30-O32-O35 -> 89654.687 | P38: =SUM(D38:O38) -> 1029891.7
C39: Venta de energía | D39: =+D40+D43+D54 -> 114651 | E39: =+E40+E43+E54 -> 101038.35 | F39: =+F40+F43+F54 -> 113848.37 | G39: =+G40+G43+G54 -> 84848.776 | H39: =+H40+H43+H54 -> 72365.248 | I39: =+I40+I43+I54 -> 69602.393 | J39: =+J40+J43+J54 -> 78870.257 | K39: =+K40+K43+K54 -> 75836.086 | ... O39: =+O40+O43+O54 -> 89654.687 | P39: =SUM(D39:O39) -> 1029891.7
C40: A Emp. Generadoras | D40: =+D41+D42 -> 56927.84 | E40: =+E41+E42 -> 46159.398 | F40: =+F41+F42 -> 55089.721 | G40: =+G41+G42 -> 26944.745 | H40: =+H41+H42 -> 14637.573 | I40: =+I41+I42 -> 14444.374 | J40: =+J41+J42 -> 22422.158 | K40: =+K41+K42 -> 19364.859 | ... O40: =+O41+O42 -> 32152.651 | P40: =SUM(D40:O40) -> 350450.71
C41: COES | D41: 56927.84 | E41: 46159.398 | F41: 55089.721 | G41: 26944.745 | H41: 14637.573 | I41: 14444.374 | J41: 22422.158 | K41: 19364.859 | L41: 14685.295 | M41: 23227.62 | N41: 24394.476 | O41: 32152.651 | P41: =SUM(D41:O41) -> 350450.71
C42: Electroperú (SWAP) | D42: 0 | E42: 0 | F42: 0 | G42: 0 | H42: 0 | I42: 0 | J42: 0 | K42: 0 | L42: 0 | M42: 0 | N42: 0 | P42: =SUM(D42:O42) -> 0
C43: A emp. Distribuidoras: | D43: =SUM(D44:D52) -> 54830.9 | E43: =SUM(E44:E52) -> 52239.07 | F43: =SUM(F44:F52) -> 55735.654 | G43: =SUM(G44:G53) -> 55075.946 | H43: =SUM(H44:H53) -> 54587.342 | I43: =SUM(I44:I53) -> 52199.137 | J43: =SUM(J44:J53) -> 53331.173 | K43: =SUM(K44:K53) -> 53704.336 | L43: =SUM(L44:L53) -> 52262.628 | M43: =SUM(M44:M53) -> 53513.975 | N43: =SUM(N44:N53) -> 53176.671 | ... P43: =SUM(P44:P53) -> 645869.37
C44: Edelnor | D44: 12092.203 | E44: 11329.898 | F44: 12293.932 | G44: 11811.546 | H44: 11678.863 | I44: 11183.292 | J44: 11369.888 | K44: 11358.021 | L44: 10996.761 | M44: 11516.386 | N44: 11381.287 | O44: =11916500.48/1000 -> 11916.5 | P44: =SUM(D44:O44) -> 138928.58
...

Sheet 2018-R2 (LDS)
C3: PRODUCCIÓN MENSUAL DE ENERGÍA ELÉCTRICA EN EGASA
C4: AÑO 2017 (MWh)
C6: CENTRALES | D6: Enero | E6: Febrero | F6: Marzo | G6: Abril | H6: Mayo | I6: Junio | J6: Julio | K6: Agosto | L6: Septiembre | M6: Octubre | N6: Noviembre | O6: Diciembre | P6: Acumulado
C7: Hidráulica
C8: Charcani I | D8: 1228.0921 | E8: 986.42803 | F8: 862.98338 | G8: 1197.3586 | H8: 1211.6252 | I8: 1206.6493 | J8: 1229.4428 | K8: 1234.0962 | L8: 1175.2787 | M8: 1209.888 | N8: 1203.1332 | O8: 1249.6844 | P8: =+SUM(D8:O8) -> 13994.66
C9: Charcani II | D9: 423.47076 | E9: 375.80717 | F9: 411.71554 | G9: 408.407 | H9: 419.742 | I9: 407.55314 | J9: 423.79279 | K9: 423.09478 | L9: 409.3038 | M9: 422.77178 | N9: 413.90879 | O9: 425.00294 | P9: =+SUM(D9:O9) -> 4964.5705
C10: Charcani III | D10: 3351.5669 | E10: 3035.1489 | F10: 3220.6894 | G10: 3267.6024 | H10: 3313.0238 | I10: 3252.841 | J10: 3336.8612 | K10: 3382.635 | L10: 3230.757 | M10: 3380.8876 | N10: 3240.9816 | O10: 3392.6956 | P10: =+SUM(D10:O10) -> 39405.691
C11: Charcani IV | D11: 9586.631 | E11: 9974.9586 | F11: 10712.93 | G11: 9620.4484 | H11: 7866.4879 | I11: 7221.2623 | J11: 8903.4353 | K11: 8834.4486 | L11: 8333.4381 | M11: 9461.5794 | N11: 9062.1557 | O11: 9489.362 | P11: =+SUM(D11:O11) -> 109067.14
C12: Charcani V | D12: 68721.664 | E12: 71753.264 | F12: 87204.526 | G12: 62141.1 | H12: 49391.121 | I12: 49949.568 | J12: 54752.707 | K12: 54393.779 | L12: 51698.256 | M12: 58453.85 | N12: 55793.44 | O12: 57876.761 | P12: =+SUM(D12:O12) -> 722130.04
C13: Charcani VI | D13: 5765.1802 | E13: 5705.8454 | F13: 6167.417 | G13: 5762.8928 | H13: 4882.6782 | I13: 4997.1142 | J13: 5497.7487 | K13: 5460.555 | L13: 5171.5088 | M13: 5834.0313 | N13: 4922.7155 | O13: 5831.0249 | P13: =+SUM(D13:O13) -> 65998.712
C14: Total Hidraúlica | D14: =SUM(D8:D13) -> 89076.605 | E14: =SUM(E8:E13) -> 91831.452 | F14: =SUM(F8:F13) -> 108580.26 | G14: =SUM(G8:G13) -> 82397.809 | H14: =SUM(H8:H13) -> 67084.678 | I14: =SUM(I8:I13) -> 67034.988 | J14: =SUM(J8:J13) -> 74143.988 | K14: =SUM(K8:K13) -> 73728.608 | ... O14: =SUM(O8:O13) -> 78264.531 | P14: =+SUM(D14:O14) -> 955560.81
C15: Térmica
C16: T.Vapor | D16: 0 | E16: 0 | F16: 0 | G16: 0 | H16: 0 | I16: 0 | J16: 0 | K16: 0 | L16: 0 | M16: 0 | N16: 0 | O16: 0 | P16: =+SUM(D16:O16) -> 0
C17: T.G.-Ciclo Combinado | D17: 28.319092 | E17: 0 | F17: 0 | G17: 0 | H17: 0 | I17: 0 | J17: 1.4692601 | K17: 0 | L17: 1.5684984 | M17: 27.835423 | N17: 1.2736733 | O17: 0 | P17: =+SUM(D17:O17) -> 60.465947
C18: Sulzers | D18: 4.6483677 | E18: 551.9029 | F18: 0 | G18: 0 | H18: 0 | I18: 0 | J18: 101.94739 | K18: 92.250461 | L18: 13.090176 | M18: 0.54703954 | N18: 0 | O18: 14.290916 | P18: =+SUM(D18:O18) -> 778.67725
C19: C.T. Mollendo | D19: 22.713676 | E19: 187.82881 | F19: 0.16011644 | G19: 20.534106 | H19: 20.170126 | I19: 0 | J19: 157.20749 | K19: 120.91541 | L19: 0 | M19: 0 | N19: 20.838456 | O19: 1.0982753 | P19: =+SUM(D19:O19) -> 551.46646
C20: C.T. Pisco | D20: 27458.054 | E20: 10168.115 | F20: 6530.9473 | G20: 4028.4454 | H20: 6715.337 | I20: 3945.6362 | J20: 1318.9612 | K20: 1254.5912 | L20: 778.56739 | M20: 1331.095 | N20: 8301.7957 | O20: 12801.087 | P20: =+SUM(D20:O20) -> 84632.631
C21: Total Térmica | D21: =SUM(D16:D20) -> 27513.735 | E21: =SUM(E16:E20) -> 10907.846 | F21: =SUM(F16:F20) -> 6531.1074 | G21: =SUM(G16:G20) -> 4048.9795 | H21: =SUM(H16:H20) -> 6735.5071 | I21: =SUM(I16:I20) -> 3945.6362 | J21: =SUM(J16:J20) -> 1579.5853 | K21: =SUM(K16:K20) -> 1467.7571 | ... O21: =SUM(O16:O20) -> 12816.476 | P21: =+SUM(D21:O21) -> 86023.241
C22: TOTAL EGASA | D22: =+D14+D21 -> 116590.34 | E22: =+E14+E21 -> 102739.3 | F22: =+F14+F21 -> 115111.37 | G22: =+G14+G21 -> 86446.789 | H22: =+H14+H21 -> 73820.186 | I22: =+I14+I21 -> 70980.624 | J22: =+J14+J21 -> 75723.573 | K22: =+K14+K21 -> 75196.366 | ... O22: =+O14+O21 -> 91081.007 | P22: =+SUM(D22:O22) -> 1041584
Q23: 1000
C24: BALANCE DE ENERGÍA EN MWh - AÑO 2018
C26: DESCRIPCIÓN | D26: Enero | E26: Febrero | F26: Marzo | G26: Abril | H26: Mayo | I26: Junio | J26: Julio | K26: Agosto | L26: Septiembre | M26: Octubre | N26: Noviembre | O26: Diciembre | P26: Acumulado
C27: Energía producida | D27: =+D28+D29 -> 116590.34 | E27: =+E28+E29 -> 102739.3 | F27: =+F28+F29 -> 115111.37 | G27: =+G28+G29 -> 86446.789 | H27: =+H28+H29 -> 73820.186 | I27: =+I28+I29 -> 70980.624 | J27: =+J28+J29 -> 75723.573 | K27: =+K28+K29 -> 75196.366 | ... O27: =+O28+O29 -> 91081.007 | P27: =SUM(D27:O27) -> 1041584
C28: Hidroeléctrica | D28: 89076.605 | E28: 91831.452 | F28: 108580.26 | G28: 82397.809 | H28: 67084.678 | I28: 67034.988 | J28: 74143.988 | K28: 73728.608 | L28: 70018.542 | M28: 78763.008 | N28: =74636334.9403163/1000 -> 74636.335 | O28: 78264.531 | P28: =SUM(D28:O28) -> 955560.81
C29: Termoeléctrica | D29: 27513.735 | E29: 10907.846 | F29: 6531.1074 | G29: 4048.9795 | H29: 6735.5071 | I29: 3945.6362 | J29: 1579.5853 | K29: 1467.7571 | L29: 793.22606 | M29: 1359.4774 | N29: =8323907.8109382/1000 -> 8323.9078 | O29: 12816.476 | P29: =SUM(D29:O29) -> 86023.241
C30: Compra de energía | D30: =+D31 -> 0 | E30: =+E31 -> 0 | F30: =+F31 -> 0 | G30: =+G31 -> 0 | H30: =+H31 -> 0 | I30: =+I31 -> 0 | J30: =+J31 -> 4111.8636 | K30: =+K31 -> 1905.4541 | ... O30: =+O31 -> 0 | P30: =SUM(D30:O30) -> 7679.3483
C31: COES | D31: 0 | E31: 0 | F31: 0 | G31: 0 | H31: 0 | I31: 0 | J31: 4111.8636 | K31: 1905.4541 | L31: 0 | M31: 1662.0306 | N31: 0 | P31: =SUM(D31:O31) -> 7679.3483
C32: Consumo propio de centrales | D32: =+D33+D34 -> 425.41875 | E32: =+E33+E34 -> 392.10484 | F32: =+F33+F34 -> 367.90234 | G32: =+G33+G34 -> 330.86296 | H32: =+H33+H34 -> 332.21455 | I32: =+I33+I34 -> 497.07396 | J32: =+J33+J34 -> 461.66019 | K32: =+K33+K34 -> 319.34972 | ... O32: =+O33+O34 -> 321.19504 | P32: =SUM(D32:O32) -> 4391.4736
C33: Hidroeléctrica | D33: 319.19512 | E33: 304.26569 | F33: 343.00388 | G33: 314.31736 | H33: 304.53582 | I33: 304.33451 | J33: 310.33159 | K33: 302.5947 | L33: 299.11276 | M33: 307.57254 | N33: 295.35651 | O33: =289.454726041317-5.79740113270283 -> 283.65732 | P33: =SUM(D33:O33) -> 3688.2778
C34: Termoeléctrica | D34: 106.22363 | E34: 87.839149 | F34: 24.898467 | G34: 16.545597 | H34: 27.67873 | I34: 192.73945 | J34: 151.3286 | K34: 16.755024 | L34: 3.2110245 | M34: 3.8782018 | N34: 34.560249 | O34: 37.537713 | P34: =SUM(D34:O34) -> 703.19584
C35: Pérdidas Sistemas Transmisión | D35: =+D36+D37 -> 1506.0752 | E35: =+E36+E37 -> 1316.062 | F35: =+F36+F37 -> 1501.3848 | G35: =+G36+G37 -> 1229.4982 | H35: =+H36+H37 -> 1113.3409 | I35: =+I36+I37 -> 876.02619 | J35: =+J36+J37 -> 916.31487 | K35: =+K36+K37 -> 1006.1535 | ... O35: =+O36+O37 -> 1217.0338 | P35: =SUM(D35:O35) -> 13755.796
C36: En muy alta tensión | D36: 602.43008 | E36: 526.42482 | F36: 600.5539 | G36: 491.7993 | H36: 445.33636 | I36: 350.41048 | J36: 366.52595 | K36: 402.4614 | L36: 375.90287 | M36: 421.63381 | N36: 432.02588 | O36: 486.81351 | P36: =SUM(D36:O36) -> 5502.3184
C37: En alta tensión | D37: 903.64512 | E37: 789.63723 | F37: 900.83086 | G37: 737.69895 | H37: 668.00454 | I37: 525.61571 | J37: 549.78892 | K37: 603.6921 | L37: 563.85431 | M37: 632.45072 | N37: 648.03882 | O37: 730.22026 | P37: =SUM(D37:O37) -> 8253.4775
C38: Energía total disponible | D38: =+D27+D30-D32-D35 -> 114658.85 | E38: =+E27+E30-E32-E35 -> 101031.13 | F38: =+F27+F30-F32-F35 -> 113242.08 | G38: =+G27+G30-G32-G35 -> 84886.428 | H38: =+H27+H30-H32-H35 -> 72374.63 | I38: =+I27+I30-I32-I35 -> 69607.524 | J38: =+J27+J30-J32-J35 -> 78457.462 | K38: =+K27+K30-K32-K35 -> 75776.316 | ... O38: =+O27+O30-O32-O35 -> 89542.778 | P38: =SUM(D38:O38) -> 1031116.1
C39: Venta de energía | D39: =+D40+D43+D54 -> 114658.85 | E39: =+E40+E43+E54 -> 101031.13 | F39: =+F40+F43+F54 -> 113242.08 | G39: =+G40+G43+G54 -> 84886.428 | H39: =+H40+H43+H54 -> 72374.63 | I39: =+I40+I43+I54 -> 69607.524 | J39: =+J40+J43+J54 -> 78457.462 | K39: =+K40+K43+K54 -> 75776.316 | ... O39: =+O40+O43+O54 -> 89542.778 | P39: =SUM(D39:O39) -> 1031116.1
C40: A Emp. Generadoras | D40: =+D41+D42 -> 58300.336 | E40: =+E41+E42 -> 47443.382 | F40: =+F41+F42 -> 55875.835 | G40: =+G41+G42 -> 28305.501 | H40: =+H41+H42 -> 15953.719 | I40: =+I41+I42 -> 15701.533 | J40: =+J41+J42 -> 23271.497 | K40: =+K41+K42 -> 20566.978 | ... O40: =+O41+O42 -> 32040.743 | P40: =SUM(D40:O40) -> 365849.46
C41: COES | D41: 58300.336 | E41: 47443.382 | F41: 55875.835 | G41: 28305.501 | H41: 15953.719 | I41: 15701.533 | J41: 23271.497 | K41: 20566.978 | L41: 15858.082 | M41: 25526.263 | N41: 27005.591 | O41: 32040.743 | P41: =SUM(D41:O41) -> 365849.46
C42: Electroperú (SWAP) | D42: 0 | E42: 0 | F42: 0 | G42: 0 | H42: 0 | I42: 0 | J42: 0 | P42: =SUM(D42:O42) -> 0
C43: A emp. Distribuidoras: | D43: =SUM(D44:D52) -> 53466.247 | E43: =SUM(E44:E52) -> 50947.865 | F43: =SUM(F44:F52) -> 54343.255 | G43: =SUM(G44:G53) -> 53752.841 | H43: =SUM(H44:H53) -> 53280.578 | I43: =SUM(I44:I53) -> 50947.108 | J43: =SUM(J44:J53) -> 52069.039 | K43: =SUM(K44:K53) -> 52442.448 | L43: =SUM(L44:L53) -> 51051.299 | M43: =SUM(M44:M53) -> 52253.439 | N43: =SUM(N44:N53) -> 51928.421 | ... P43: =SUM(P44:P53) -> 631695.08
C44: Edelnor | D44: 12092.203 | E44: 11329.898 | F44: 12293.932 | G44: 11811.546 | H44: 11678.863 | I44: 11183.292 | J44: 11369.888 | K44: 11358.021 | L44: 10996.761 | M44: 11516.386 | N44: 11381.287 | O44: 11916.5 | P44: =SUM(D44:O44) -> 138928.58
...

Sheet 2019
C3: PRODUCCIÓN MENSUAL DE ENERGÍA ELÉCTRICA EN EGASA
C4: AÑO 2017 (MWh)
C6: CENTRALES | D6: Enero | E6: Febrero | F6: Marzo | G6: Abril | H6: Mayo | I6: Junio | J6: Julio | K6: Agosto | L6: Septiembre | M6: Octubre | N6: Noviembre | O6: Diciembre | P6: Acumulado
C7: Hidráulica
C8: Charcani I | D8: 1131.6971 | P8: =+SUM(D8:O8) -> 1131.6971
C9: Charcani II | D9: 404.73452 | P9: =+SUM(D9:O9) -> 404.73452
C10: Charcani III | D10: 3164.3521 | P10: =+SUM(D10:O10) -> 3164.3521
C11: Charcani IV | D11: 7358.1597 | P11: =+SUM(D11:O11) -> 7358.1597
C12: Charcani V | D12: 44993.963 | P12: =+SUM(D12:O12) -> 44993.963
C13: Charcani VI | D13: 4089.3769 | P13: =+SUM(D13:O13) -> 4089.3769
C14: Total Hidraúlica | D14: =SUM(D8:D13) -> 61142.283 | E14: =SUM(E8:E13) -> 0 | F14: =SUM(F8:F13) -> 0 | G14: =SUM(G8:G13) -> 0 | H14: =SUM(H8:H13) -> 0 | I14: =SUM(I8:I13) -> 0 | J14: =SUM(J8:J13) -> 0 | K14: =SUM(K8:K13) -> 0 | ... O14: =SUM(O8:O13) -> 0 | P14: =+SUM(D14:O14) -> 61142.283
C15: Térmica
C16: T.Vapor | D16: 0 | P16: =+SUM(D16:O16) -> 0
C17: T.G.-Ciclo Combinado | D17: 11.521423 | P17: =+SUM(D17:O17) -> 11.521423
C18: Sulzers | D18: 701.38252 | P18: =+SUM(D18:O18) -> 701.38252
C19: C.T. Mollendo | D19: 1338.8287 | P19: =+SUM(D19:O19) -> 1338.8287
C20: C.T. Pisco | D20: 35832.495 | P20: =+SUM(D20:O20) -> 35832.495
C21: Total Térmica | D21: =SUM(D16:D20) -> 37884.227 | E21: =SUM(E16:E20) -> 0 | F21: =SUM(F16:F20) -> 0 | G21: =SUM(G16:G20) -> 0 | H21: =SUM(H16:H20) -> 0 | I21: =SUM(I16:I20) -> 0 | J21: =SUM(J16:J20) -> 0 | K21: =SUM(K16:K20) -> 0 | ... O21: =SUM(O16:O20) -> 0 | P21: =+SUM(D21:O21) -> 37884.227
C22: TOTAL EGASA | D22: =+D14+D21 -> 99026.51 | E22: =+E14+E21 -> 0 | F22: =+F14+F21 -> 0 | G22: =+G14+G21 -> 0 | H22: =+H14+H21 -> 0 | I22: =+I14+I21 -> 0 | J22: =+J14+J21 -> 0 | K22: =+K14+K21 -> 0 | ... O22: =+O14+O21 -> 0 | P22: =+SUM(D22:O22) -> 99026.51
Q23: 1000
C24: BALANCE DE ENERGÍA EN MWh - AÑO 2019
C26: DESCRIPCIÓN | D26: Enero | E26: Febrero | F26: Marzo | G26: Abril | H26: Mayo | I26: Junio | J26: Julio | K26: Agosto | L26: Septiembre | M26: Octubre | N26: Noviembre | O26: Diciembre | P26: Acumulado | Q26: 1000
C27: Energía producida | D27: =+D28+D29 -> 84554.598 | E27: =+E28+E29 -> 109587.91 | F27: =+F28+F29 -> 117590.71 | G27: =+G28+G29 -> 90100.445 | H27: =+H28+H29 -> 71163.375 | I27: =+I28+I29 -> 69812.027 | J27: =+J28+J29 -> 71220.667 | K27: =+K28+K29 -> 72924.135 | ... O27: =+O28+O29 -> 75142.669 | P27: =SUM(D27:O27) -> 992981.49
C28: Hidroeléctrica | D28: 74934.188 | E28: 97541.913 | F28: 108165.24 | G28: 90073.526 | H28: 71143.135 | I28: 69785.813 | J28: 71183.253 | K28: 72913.252 | L28: 70558.254 | M28: 78874.542 | N28: 81026.361 | O28: 75028.636 | P28: =SUM(D28:O28) -> 961228.11
C29: Termoeléctrica | D29: 9620.4093 | E29: 12045.995 | F29: 9425.4728 | G29: 26.919347 | H29: 20.24018 | I29: 26.213821 | J29: 37.413505 | K29: 10.883162 | L29: 349.61303 | M29: 32.466166 | N29: 43.720482 | O29: 114.0331 | P29: =SUM(D29:O29) -> 31753.38
C30: Compra de energía | D30: =+D31 -> 0 | E30: =+E31 -> 0 | F30: =+F31 -> 0 | G30: =+G31 -> 0 | H30: =+H31 -> 0 | I30: =+I31 -> 0 | J30: =+J31 -> 0 | K30: =+K31 -> 0 | ... O30: =+O31 -> 0 | P30: =SUM(D30:O30) -> 0
C31: COES | D31: 0 | E31: 0 | F31: 0 | G31: 0 | H31: 0 | I31: 0 | L31: 0 | M31: 0 | N31: 0 | P31: =SUM(D31:O31) -> 0
C32: Consumo propio de centrales | D32: =+D33+D34 -> 288.12784 | E32: =+E33+E34 -> 292.57779 | F32: =+F33+F34 -> 285.93088 | G32: =+G33+G34 -> 315.76657 | H32: =+H33+H34 -> 289.84 | I32: =+I33+I34 -> 295.73388 | J32: =+J33+J34 -> 300.36436 | K32: =+K33+K34 -> 307.26589 | ... O32: =+O33+O34 -> 310.93107 | P32: =SUM(D32:O32) -> 3597.2973
C33: Hidroeléctrica | D33: 256.33946 | E33: 252.02609 | F33: 259.60489 | G33: 315.52348 | H33: 289.65 | I33: 295.73113 | J33: 297.81537 | K33: 306.12469 | L33: 294.24895 | M33: 306.24528 | N33: 293.32614 | O33: 302.78812 | P33: =SUM(D33:O33) -> 3469.4236 | Q33: =+P33/12 -> 289.11863
C34: Termoeléctrica | D34: 31.788377 | E34: 40.551697 | F34: 26.325984 | G34: 0.24309471 | H34: 0.19 | I34: 0.0027520048 | J34: 2.5489824 | K34: 1.1411987 | L34: 14.59292 | M34: 0.26472483 | N34: 2.0809746 | O34: 8.142951 | P34: =SUM(D34:O34) -> 127.87366 | Q34: =+P34/12 -> 10.656138
C35: Pérdidas Sistemas Transmisión | D35: =+D36+D37 -> 1159.4471 | E35: =+E36+E37 -> 1212.2681 | F35: =+F36+F37 -> 1543.7284 | G35: =+G36+G37 -> 1407.3392 | H35: =+H36+H37 -> 1105.5689 | I35: =+I36+I37 -> 1155.9227 | J35: =+J36+J37 -> 1091.9823 | K35: =+K36+K37 -> 996.19238 | ... O35: =+O36+O37 -> 1062.7054 | P35: =SUM(D35:O35) -> 14731.337
C36: En muy alta tensión | D36: 463.77886 | E36: 484.90725 | F36: 617.49137 | G36: 562.93569 | H36: 442.22757 | I36: 462.36907 | J36: 436.7929 | K36: 398.47695 | L36: 590.0607 | M36: 551.32274 | N36: 457.0895 | O36: 425.08215 | P36: =SUM(D36:O36) -> 5892.5347
C37: En alta tensión | D37: 695.66828 | E37: 727.36087 | F37: 926.23705 | G37: 844.40353 | H37: 663.34135 | I37: 693.5536 | J37: 655.18935 | K37: 597.71543 | L37: 885.09105 | M37: 826.98411 | N37: 685.63425 | O37: 637.62323 | P37: =SUM(D37:O37) -> 8838.8021
C38: Energía total disponible | D38: =+D27+D30-D32-D35 -> 83107.023 | E38: =+E27+E30-E32-E35 -> 108083.06 | F38: =+F27+F30-F32-F35 -> 115761.05 | G38: =+G27+G30-G32-G35 -> 88377.34 | H38: =+H27+H30-H32-H35 -> 69767.966 | I38: =+I27+I30-I32-I35 -> 68360.371 | J38: =+J27+J30-J32-J35 -> 69828.32 | K38: =+K27+K30-K32-K35 -> 71620.677 | ... O38: =+O27+O30-O32-O35 -> 73769.032 | P38: =SUM(D38:O38) -> 974652.85
C39: Venta de energía | D39: =+D40+D43+D54 -> 83107.023 | E39: =+E40+E43+E54 -> 108083.06 | F39: =+F40+F43+F54 -> 115761.05 | G39: =+G40+G43+G54 -> 88377.34 | H39: =+H40+H43+H54 -> 69767.966 | I39: =+I40+I43+I54 -> 68360.371 | J39: =+J40+J43+J54 -> 69828.32 | K39: =+K40+K43+K54 -> 71620.677 | ... O39: =+O40+O43+O54 -> 73769.032 | P39: =SUM(D39:O39) -> 974652.85
C40: A Emp. Generadoras | D40: =+D41+D42 -> 17903.533 | E40: =+E41+E42 -> 47292.29 | F40: =+F41+F42 -> 50636.335 | G40: =+G41+G42 -> 28152.275 | H40: =+H41+H42 -> 9379.5069 | I40: =+I41+I42 -> 11732.865 | J40: =+J41+J42 -> 12141.949 | K40: =+K41+K42 -> 13745.96 | ... O40: =+O41+O42 -> 12774.929 | P40: =SUM(D40:O40) -> 255556.85
C41: COES | D41: 17903.533 | E41: 47292.29 | F41: 50636.335 | G41: 28152.275 | H41: 9379.5069 | I41: 11732.865 | J41: 12141.949 | K41: 13745.96 | L41: 12195.663 | M41: 18247.86 | N41: 21353.685 | O41: 12774.929 | P41: =SUM(D41:O41) -> 255556.85
C42: Electroperú (SWAP) | D42: 0 | E42: 0 | F42: 0 | G42: 0 | H42: 0 | I42: 0 | J42: 0 | K42: 0 | L42: 0 | M42: 0 | N42: 0 | P42: =SUM(D42:O42) -> 0
C43: A emp. Distribuidoras: | D43: =SUM(D44:D53) -> 61496.456 | E43: =SUM(E44:E53) -> 57056.273 | F43: =SUM(F44:F53) -> 60725.64 | G43: =SUM(G44:G53) -> 56068.42 | H43: =SUM(H44:H53) -> 55872.385 | I43: =SUM(I44:I53) -> 52363.767 | J43: =SUM(J44:J53) -> 53561.128 | K43: =SUM(K44:K53) -> 53935.014 | ... P43: =SUM(P44:P53) -> 670718.31
C44: Edelnor | D44: 12330.971 | E44: 11850.139 | F44: 12768.57 | G44: 11718.532 | H44: 11686.984 | I44: 11112.23 | J44: 11344.502 | K44: 11320.7 | L44: 11002.891 | M44: 11449.635 | N44: 11333.036 | O44: =11887760.2/1000 -> 11887.76 | P44: =SUM(D44:O44) -> 139805.95
...

Sheet 2019-R1
C3: PRODUCCIÓN MENSUAL DE ENERGÍA ELÉCTRICA EN EGASA
C4: AÑO 2017 (MWh)
C6: CENTRALES | D6: Enero | E6: Febrero | F6: Marzo | G6: Abril | H6: Mayo | I6: Junio | J6: Julio | K6: Agosto | L6: Septiembre | M6: Octubre | N6: Noviembre | O6: Diciembre | P6: Acumulado
C7: Hidráulica
C8: Charcani I | D8: 1131.6971 | P8: =+SUM(D8:O8) -> 1131.6971
C9: Charcani II | D9: 404.73452 | P9: =+SUM(D9:O9) -> 404.73452
C10: Charcani III | D10: 3164.3521 | P10: =+SUM(D10:O10) -> 3164.3521
C11: Charcani IV | D11: 7358.1597 | P11: =+SUM(D11:O11) -> 7358.1597
C12: Charcani V | D12: 44993.963 | P12: =+SUM(D12:O12) -> 44993.963
C13: Charcani VI | D13: 4089.3769 | P13: =+SUM(D13:O13) -> 4089.3769
C14: Total Hidraúlica | D14: =SUM(D8:D13) -> 61142.283 | E14: =SUM(E8:E13) -> 0 | F14: =SUM(F8:F13) -> 0 | G14: =SUM(G8:G13) -> 0 | H14: =SUM(H8:H13) -> 0 | I14: =SUM(I8:I13) -> 0 | J14: =SUM(J8:J13) -> 0 | K14: =SUM(K8:K13) -> 0 | ... O14: =SUM(O8:O13) -> 0 | P14: =+SUM(D14:O14) -> 61142.283
C15: Térmica
C16: T.Vapor | D16: 0 | P16: =+SUM(D16:O16) -> 0
C17: T.G.-Ciclo Combinado | D17: 11.521423 | P17: =+SUM(D17:O17) -> 11.521423
C18: Sulzers | D18: 701.38252 | P18: =+SUM(D18:O18) -> 701.38252
C19: C.T. Mollendo | D19: 1338.8287 | P19: =+SUM(D19:O19) -> 1338.8287
C20: C.T. Pisco | D20: 35832.495 | P20: =+SUM(D20:O20) -> 35832.495
C21: Total Térmica | D21: =SUM(D16:D20) -> 37884.227 | E21: =SUM(E16:E20) -> 0 | F21: =SUM(F16:F20) -> 0 | G21: =SUM(G16:G20) -> 0 | H21: =SUM(H16:H20) -> 0 | I21: =SUM(I16:I20) -> 0 | J21: =SUM(J16:J20) -> 0 | K21: =SUM(K16:K20) -> 0 | ... O21: =SUM(O16:O20) -> 0 | P21: =+SUM(D21:O21) -> 37884.227
C22: TOTAL EGASA | D22: =+D14+D21 -> 99026.51 | E22: =+E14+E21 -> 0 | F22: =+F14+F21 -> 0 | G22: =+G14+G21 -> 0 | H22: =+H14+H21 -> 0 | I22: =+I14+I21 -> 0 | J22: =+J14+J21 -> 0 | K22: =+K14+K21 -> 0 | ... O22: =+O14+O21 -> 0 | P22: =+SUM(D22:O22) -> 99026.51
Q23: 1000
C24: BALANCE DE ENERGÍA EN MWh - AÑO 2019
C26: DESCRIPCIÓN | D26: Enero | E26: Febrero | F26: Marzo | G26: Abril | H26: Mayo | I26: Junio | J26: Julio | K26: Agosto | L26: Septiembre | M26: Octubre | N26: Noviembre | O26: Diciembre | P26: Acumulado
C27: Energía producida | D27: =+D28+D29 -> 84554.598 | E27: =+E28+E29 -> 109587.91 | F27: =+F28+F29 -> 117590.71 | G27: =+G28+G29 -> 90100.445 | H27: =+H28+H29 -> 71163.375 | I27: =+I28+I29 -> 69812.027 | J27: =+J28+J29 -> 71220.667 | K27: =+K28+K29 -> 72924.135 | ... O27: =+O28+O29 -> 75142.669 | P27: =SUM(D27:O27) -> 992981.49
C28: Hidroeléctrica | D28: 74934.188 | E28: 97541.913 | F28: 108165.24 | G28: 90073.526 | H28: 71143.135 | I28: 69785.813 | J28: 71183.253 | K28: 72913.252 | L28: 70558.254 | M28: =+'2019'!M28 -> 78874.542 | N28: =+'2019'!N28 -> 81026.361 | O28: =+'2019'!O28 -> 75028.636 | P28: =SUM(D28:O28) -> 961228.11
C29: Termoeléctrica | D29: 9620.4093 | E29: 12045.995 | F29: 9425.4728 | G29: 26.919347 | H29: 20.24018 | I29: 26.213821 | J29: 37.413505 | K29: 10.883162 | L29: 349.61303 | M29: =+'2019'!M29 -> 32.466166 | N29: =+'2019'!N29 -> 43.720482 | O29: =+'2019'!O29 -> 114.0331 | P29: =SUM(D29:O29) -> 31753.38
C30: Compra de energía | D30: =+D31 -> 0 | E30: =+E31 -> 0 | F30: =+F31 -> 0 | G30: =+G31 -> 0 | H30: =+H31 -> 0 | I30: =+I31 -> 0 | J30: =+J31 -> 0 | K30: =+K31 -> 0 | ... O30: =+O31 -> 0 | P30: =SUM(D30:O30) -> 0
C31: COES | D31: 0 | E31: 0 | F31: 0 | G31: 0 | H31: 0 | I31: 0 | J31: 0 | K31: 0 | L31: 0 | N31: 0 | P31: =SUM(D31:O31) -> 0
C32: Consumo propio de centrales | D32: =+D33+D34 -> 288.12784 | E32: =+E33+E34 -> 292.57779 | F32: =+F33+F34 -> 285.93088 | G32: =+G33+G34 -> 315.76657 | H32: =+H33+H34 -> 289.84 | I32: =+I33+I34 -> 295.73388 | J32: =+J33+J34 -> 300.36436 | K32: =+K33+K34 -> 307.26589 | ... O32: =+O33+O34 -> 310.93107 | P32: =SUM(D32:O32) -> 3597.2973
C33: Hidroeléctrica | D33: 256.33946 | E33: 252.02609 | F33: 259.60489 | G33: 315.52348 | H33: 289.65 | I33: 295.73113 | J33: 297.81537 | K33: 306.12469 | L33: 294.24895 | M33: =+'2019'!M33 -> 306.24528 | N33: =+'2019'!N33 -> 293.32614 | O33: =+'2019'!O33 -> 302.78812 | P33: =SUM(D33:O33) -> 3469.4236
C34: Termoeléctrica | D34: 31.788377 | E34: 40.551697 | F34: 26.325984 | G34: 0.24309471 | H34: 0.19 | I34: 0.0027520048 | J34: 2.5489824 | K34: 1.1411987 | L34: 14.59292 | M34: =+'2019'!M34 -> 0.26472483 | N34: =+'2019'!N34 -> 2.0809746 | O34: =+'2019'!O34 -> 8.142951 | P34: =SUM(D34:O34) -> 127.87366
C35: Pérdidas Sistemas Transmisión | D35: =+D36+D37 -> 1158.9719 | E35: =+E36+E37 -> 1116.8605 | F35: =+F36+F37 -> 1546.8166 | G35: =+G36+G37 -> 1283.408 | H35: =+H36+H37 -> 1135.0445 | I35: =+I36+I37 -> 1155.9227 | J35: =+J36+J37 -> 1091.9823 | K35: =+K36+K37 -> 992.72224 | ... O35: =+O36+O37 -> 1062.7054 | P35: =SUM(D35:O35) -> 14540.616
C36: En muy alta tensión | D36: 463.58877 | E36: 446.7442 | F36: 618.72663 | G36: 513.3632 | H36: 454.01781 | I36: 462.36907 | J36: 436.7929 | K36: 397.08889 | L36: 590.0607 | M36: =+'2019'!M36 -> 551.32274 | N36: =+'2019'!N36 -> 457.0895 | O36: =+'2019'!O36 -> 425.08215 | P36: =SUM(D36:O36) -> 5816.2466
C37: En alta tensión | D37: 695.38315 | E37: 670.1163 | F37: 928.08995 | G37: 770.0448 | H37: 681.02671 | I37: 693.5536 | J37: 655.18935 | K37: 595.63334 | L37: 885.09105 | M37: =+'2019'!M37 -> 826.98411 | N37: =+'2019'!N37 -> 685.63425 | O37: =+'2019'!O37 -> 637.62323 | P37: =SUM(D37:O37) -> 8724.3699
C38: Energía total disponible | D38: =+D27+D30-D32-D35 -> 83107.498 | E38: =+E27+E30-E32-E35 -> 108178.47 | F38: =+F27+F30-F32-F35 -> 115757.96 | G38: =+G27+G30-G32-G35 -> 88501.271 | H38: =+H27+H30-H32-H35 -> 69738.491 | I38: =+I27+I30-I32-I35 -> 68360.371 | J38: =+J27+J30-J32-J35 -> 69828.32 | K38: =+K27+K30-K32-K35 -> 71624.147 | ... O38: =+O27+O30-O32-O35 -> 73769.032 | P38: =SUM(D38:O38) -> 974843.58
C39: Venta de energía | D39: =+D40+D43+D54 -> 83107.498 | E39: =+E40+E43+E54 -> 108178.47 | F39: =+F40+F43+F54 -> 115757.96 | G39: =+G40+G43+G54 -> 88501.271 | H39: =+H40+H43+H54 -> 69738.491 | I39: =+I40+I43+I54 -> 68360.371 | J39: =+J40+J43+J54 -> 69828.32 | K39: =+K40+K43+K54 -> 71624.147 | ... O39: =+O40+O43+O54 -> 73769.032 | P39: =SUM(D39:O39) -> 974843.58
C40: A Emp. Generadoras | D40: =+D41+D42 -> 17903.533 | E40: =+E41+E42 -> 47387.778 | F40: =+F41+F42 -> 50636.335 | G40: =+G41+G42 -> 28276.113 | H40: =+H41+H42 -> 9350.0313 | I40: =+I41+I42 -> 11732.865 | J40: =+J41+J42 -> 12141.949 | K40: =+K41+K42 -> 13745.96 | ... O40: =+O41+O42 -> 12774.929 | P40: =SUM(D40:O40) -> 255746.7
C41: COES | D41: 17903.533 | E41: 47387.778 | F41: 50636.335 | G41: 28276.113 | H41: 9350.0313 | I41: 11732.865 | J41: 12141.949 | K41: 13745.96 | L41: 12195.663 | M41: =+'2019'!M41 -> 18247.86 | N41: =+'2019'!N41 -> 21353.685 | O41: =+'2019'!O41 -> 12774.929 | P41: =SUM(D41:O41) -> 255746.7
C42: Electroperú (SWAP) | D42: 0 | E42: 0 | F42: 0 | G42: 0 | H42: 0 | I42: 0 | J42: 0 | K42: 0 | L42: 0 | M42: 0 | N42: 0 | P42: =SUM(D42:O42) -> 0
C43: A emp. Distribuidoras: | D43: =SUM(D44:D53) -> 61496.932 | E43: =SUM(E44:E53) -> 57056.193 | F43: =SUM(F44:F53) -> 60722.552 | G43: =SUM(G44:G53) -> 56068.513 | H43: =SUM(H44:H53) -> 55872.385 | I43: =SUM(I44:I53) -> 52363.767 | J43: =SUM(J44:J53) -> 53561.128 | K43: =SUM(K44:K53) -> 53938.484 | ... P43: =SUM(P44:P53) -> 670719.18
C44: Edelnor | D44: 12330.971 | E44: 11850.139 | F44: 12765.481 | G44: 11718.532 | H44: 11686.984 | I44: 11112.23 | J44: 11344.502 | K44: 11320.722 | L44: 11002.891 | M44: =+'2019'!M44 -> 11449.635 | N44: =+'2019'!N44 -> 11333.036 | O44: 11887.76 | P44: =SUM(D44:O44) -> 139802.88
...

Sheet 2019-R2
C3: PRODUCCIÓN MENSUAL DE ENERGÍA ELÉCTRICA EN EGASA
C4: AÑO 2017 (MWh)
C6: CENTRALES | D6: Enero | E6: Febrero | F6: Marzo | G6: Abril | H6: Mayo | I6: Junio | J6: Julio | K6: Agosto | L6: Septiembre | M6: Octubre | N6: Noviembre | O6: Diciembre | P6: Acumulado
C7: Hidráulica
C8: Charcani I | D8: 1240.9939 | E8: 998.70378 | F8: 1234.4386 | G8: 1199.7256 | H8: 1243.9933 | I8: 1199.6498 | J8: 1214.4944 | K8: 1233.4055 | L8: 1162.8326 | M8: 1217.8175 | N8: 1208.276 | O8: 1230.0419 | P8: =+SUM(D8:O8) -> 14384.373
C9: Charcani II | D9: 418.88091 | E9: 312.43324 | F9: 413.71202 | G9: 407.00296 | H9: 415.04507 | I9: 405.40372 | J9: 423.37137 | K9: 421.52901 | L9: 413.99181 | M9: 421.20926 | N9: 414.69397 | O9: 423.40792 | P9: =+SUM(D9:O9) -> 4890.6813
C10: Charcani III | D10: 3355.079 | E10: 2734.1932 | F10: 3343.8868 | G10: 3273.739 | H10: 3325.7171 | I10: 3239.9702 | J10: 3315.019 | K10: 3377.7075 | L10: 3284.4659 | M10: 3396.7428 | N10: 3355.7372 | O10: 3424.8707 | P10: =+SUM(D10:O10) -> 39427.128
C11: Charcani IV | D11: 9128.7619 | E11: 7711.1607 | F11: 8815.5331 | G11: 9375.8924 | H11: 8551.3533 | I11: 8296.3259 | J11: 8302.6152 | K11: 8290.0216 | L11: 8357.9532 | M11: 9505.9844 | N11: 9794.5937 | O11: 8153.2551 | P11: =+SUM(D11:O11) -> 104283.45
C12: Charcani V | D12: 55201.712 | E12: 81546.705 | F12: 88417.859 | G12: 70217.66 | H12: 53420.797 | I12: 51705.77 | J12: 52709.714 | K12: 54146.048 | L12: 52136.686 | M12: 58454.391 | N12: 60178.444 | O12: 56312.452 | P12: =+SUM(D12:O12) -> 734448.24
C13: Charcani VI | D13: 5588.761 | E13: 4238.7171 | F13: 5939.8058 | G13: 5599.506 | H13: 4186.2291 | I13: 4938.6942 | J13: 5218.039 | K13: 5444.5401 | L13: 5202.3246 | M13: 5878.3971 | N13: 6074.6164 | O13: 5484.6079 | P13: =+SUM(D13:O13) -> 63794.238
